<robot name="test_robot">
   <!-- <link name="link1" />
    <link name="link2" />
    <link name="link3" />
    <link name="link4" />
    <joint name="joint1" type="continuous">
        <parent link="link1"/>
        <child link="link2"/>
        <origin xyz="5 3 0" rpy="0 0 0" />
        <axis xyz="-0.9 0.15 0" />
    </joint> 
    <joint name="joint2" type="continuous">
        <parent link="link1"/>
        <child link="link3"/>
        <origin xyz="-2 5 0" rpy="0 0 1.57" />
        <axis xyz="-0.707 0.707 0" />
    </joint> 
    <joint name="joint3" type="continuous">
        <parent link="link3"/>
        <child link="link4"/>
        <origin xyz="5 0 0" rpy="0 0 -1.57" />
        <axis xyz="0.707 -0.707 0" />
    </joint>-->
    <link name="world"/>
    <link name="base_link"/>
    <link name="link1"/>
    <link name="link2"/>
    <link name="link3"/>
    <link name="link4"/>
    <link name="link5"/>
    <link name="link6"/>
    <joint name="base" type="continuous">
        <parent link="world" />
        <child link="base_link" />
        <origin rpy="0.0 0.0 0.0" xyz="0.0 0.0 0.0"/>
    </joint>
    <joint name="joint1" type="continuous">
        <parent link="base_link" />
        <child link="link1" />
        <origin rpy="0.0 0.0 0.0" xyz="0.0 0.0 0.089159"/>
        <axis xyz="0 0 1"/> <!--Ruota attorno z-->
    </joint>
    <joint name="joint2" type="continuous">
        <parent link="link1"/>
        <child link="link2"/>
        <origin rpy="0.0 0.0 0.0" xyz="0.425 0.0 0.0"/>
        <axis xyz="0 1 0"/> <!--Ruota attorno y-->
    </joint>
    <joint name="joint3" type="continuous">
        <parent link="link2"/>
        <child link="link3"/>
        <origin rpy="0.0 0.0 0.0" xyz="0.39225 0.0 0.0"/>
        <axis xyz="1 0 0"/>
    </joint>
    <joint name="joint4" type="continuous" >
        <parent link="link3"/>
        <child link="link4"/>
        <origin rpy="0.0 0.0 0.0" xyz="0.0 0.0 0.10915"/>
        <axis xyz="0 0 0"/>
    </joint>
    <joint name="joint5" type="continuous" >
        <parent link="link4"/>
        <child link="link5"/>
        <origin rpy="0.0 0.0 0.0" xyz="0.0 0.0 0.09456"/>
        <axis xyz="0 0 0"/>
    </joint>
    <joint name="joint6" type="continuous" >
        <parent link="link5"/>
        <child link="link6"/>
        <origin rpy="0.0 0.0 0.0" xyz="0.0 0.0 0.0823"/>
        <axis xyz="0 0 0"/>
    </joint>
</robot>