<?xml version="1.0"?>
<robot name="myfirst">

  <!--COLORE BASE -->
  <material name="white">
    <color rgba="1 1 1 1"/>  
  </material>

  <!-- COLORE LINK VERICIALI -->
  <material name="blue">
    <color rgba="0 0 0.8 1"/>
  </material>

  <!-- COLORE LINK ORRIZONTALI -->
  <material name="lightgreen">
    <color rgba="0.45 1 0 1"/>
  </material>


  <link name="base_link">
    <visual>
      <geometry>
        <cylinder length="0.1" radius="0.5"/>
      </geometry>
      <material name="white"/>
    </visual>
  </link>

  <link name="H">
    <visual>
      <geometry>
        <box size="0.25 0.25 0.4"/>
      </geometry>
      <origin xyz="0.0 0.0 0.2"/>
      <material name="blue"/>
    </visual>
  </link>

  <!-- COLLEGO BASE E H -->
  <joint name="joint_base_to_H" type="fixed">
    <parent link="base_link"/>
    <child link="H"/>
    <origin rpy="0.0 0.0 3.14"/>
  </joint>

  <link name="M1">
    <visual>
      <geometry>
        <cylinder length="0.15" radius="0.1"/>
      </geometry>
    </visual>
  </link>
  
  
  <joint name="joint_H_to_M1" type="revolute">
    <parent link="H"/>
    <child link="M1"/>
    <origin xyz="0.0 0.0 0.45" rpy="0.0 0.0 0.0"/>
    <limit effort="1000" velocity="1.0" lower="-2.5" upper="2.5" />
    <axis xyz="0 0 1"/>
  </joint>

  <link name="Li">
    <visual>
      <geometry>
        <box size="0.2 0.2 0.3"/>
      </geometry>
      <origin rpy= "0 1.57 0" xyz="0.15 0.0 0.0"/>
      <material name="lightgreen"/>
    </visual>
  </link>

  <joint name="joint_M1_to_Li" type="fixed">
    <parent link="M1"/>
    <child link="Li"/>
  </joint>

  <link name ="M2">
    <visual>
    <geometry>
      <cylinder length="0.15" radius="0.1"/>
    </geometry>
    </visual>
  </link>

  <joint name="joint_Li_to_M2" type="revolute">
    <parent link="Li"/>
    <child link="M2"/>
    <origin xyz="0.3 0.0 0.0" rpy="0.0 0.0 0.0"/>
    <limit effort="1000" velocity="1.0" lower="-2.0" upper="2.0"/>
    <axis xyz="0 0 1"/>
  </joint>

  <link name="L0" type="fixed">
    <visual>
      <geometry>
        <box size="0.2 0.2 0.3"/>
      </geometry>
      <material name="lightgreen"/>
      <origin xyz="0.150 0.0 0.0" rpy="0 1.57 0"/>
    </visual>
  </link>

  <joint name="joint_M2_to_L0" type="fixed">
    <parent link="M2"/>
    <child link="L0"/>
    <origin rpy="0.0 0.0 0.0"/>
  </joint>

  <link name="M3">
    <visual>
      <geometry>
        <cylinder length="0.25" radius="0.07"/>   
      </geometry>
    </visual>
  </link>

  <joint name="joint_L0_to_M3" type="fixed">
    <parent link="L0"/>
    <child link="M3"/>
    <origin xyz="0.300 0.0 0.0"/>
  </joint>

  <link name="L4">
    <visual>
      <geometry>
        <cylinder length="0.5" radius="0.05"/>  
      </geometry>
      <origin xyz="0.0 0.0 -0.1"/>
      <material name="blue"/>
    </visual>
  </link>

  <joint name="joint_M3_to_L4" type="prismatic">
    <parent link="M3"/>
    <child link="L4"/>
    <origin  rpy="3.14 0.0 0.0"/>
    <limit effort="1000" velocity="1.0" lower="0" upper="0.45"/>
    <axis xyz="0 0 1"/>
  </joint>

  <!--COLLEGAMENTO CILINDRO ROTAZIONALE SOTTO IL GIUNTO PRISMATICO-->
  <link name="Rotate_endEffector">
    <visual>
      <geometry>
        <cylinder radius="0.05" length="0.1"/>
      </geometry>
    </visual>
  </link>

  <joint name="joint_L4_to_Rotate_endEffector" type="revolute">
    <parent link="L4"/>
    <child link="Rotate_endEffector"/>
    <origin xyz="0.0 0.0 0.2" rpy="0.0 0.0 0.0"/>
    <limit effort="1000" velocity="1.0" lower="-3.0" upper="3.0"/>
    <axis xyz="0 0 1"/>
  </joint>
</robot>
